[2024-04-15T17:07:00.281+0000] {taskinstance.py:1957} INFO - Dependencies all met for dep_context=non-requeueable deps ti=<TaskInstance: dbt_visualization.generate_visualizations manual__2024-04-15T17:06:57.902157+00:00 [queued]>
[2024-04-15T17:07:00.290+0000] {taskinstance.py:1957} INFO - Dependencies all met for dep_context=requeueable deps ti=<TaskInstance: dbt_visualization.generate_visualizations manual__2024-04-15T17:06:57.902157+00:00 [queued]>
[2024-04-15T17:07:00.290+0000] {taskinstance.py:2171} INFO - Starting attempt 1 of 2
[2024-04-15T17:07:00.310+0000] {taskinstance.py:2192} INFO - Executing <Task(PythonOperator): generate_visualizations> on 2024-04-15 17:06:57.902157+00:00
[2024-04-15T17:07:00.319+0000] {standard_task_runner.py:60} INFO - Started process 6315 to run task
[2024-04-15T17:07:00.322+0000] {standard_task_runner.py:87} INFO - Running: ['***', 'tasks', 'run', 'dbt_visualization', 'generate_visualizations', 'manual__2024-04-15T17:06:57.902157+00:00', '--job-id', '119', '--raw', '--subdir', 'DAGS_FOLDER/dbt_visualization.py', '--cfg-path', '/tmp/tmpi8a9yonu']
[2024-04-15T17:07:00.325+0000] {standard_task_runner.py:88} INFO - Job 119: Subtask generate_visualizations
[2024-04-15T17:07:00.368+0000] {task_command.py:423} INFO - Running <TaskInstance: dbt_visualization.generate_visualizations manual__2024-04-15T17:06:57.902157+00:00 [running]> on host ec3d883e7b78
[2024-04-15T17:07:00.472+0000] {taskinstance.py:2481} INFO - Exporting env vars: AIRFLOW_CTX_DAG_EMAIL='66130047@dpu.ac.th' AIRFLOW_CTX_DAG_OWNER='***' AIRFLOW_CTX_DAG_ID='dbt_visualization' AIRFLOW_CTX_TASK_ID='generate_visualizations' AIRFLOW_CTX_EXECUTION_DATE='2024-04-15T17:06:57.902157+00:00' AIRFLOW_CTX_TRY_NUMBER='1' AIRFLOW_CTX_DAG_RUN_ID='manual__2024-04-15T17:06:57.902157+00:00'
[2024-04-15T17:07:00.484+0000] {base.py:83} INFO - Using connection ID 'my_***_conn' for task execution.
[2024-04-15T17:07:00.502+0000] {logging_mixin.py:188} WARNING - /opt/***/dags/dbt_visualization.py:28 UserWarning: pandas only supports SQLAlchemy connectable (engine/connection) or database string URI or sqlite3 DBAPI2 connection. Other DBAPI2 objects are not tested. Please consider using SQLAlchemy.
[2024-04-15T17:07:00.543+0000] {taskinstance.py:2699} ERROR - Task failed with exception
Traceback (most recent call last):
  File "/home/airflow/.local/lib/python3.8/site-packages/pandas/core/indexes/base.py", line 3653, in get_loc
    return self._engine.get_loc(casted_key)
  File "pandas/_libs/index.pyx", line 147, in pandas._libs.index.IndexEngine.get_loc
  File "pandas/_libs/index.pyx", line 176, in pandas._libs.index.IndexEngine.get_loc
  File "pandas/_libs/hashtable_class_helper.pxi", line 7080, in pandas._libs.hashtable.PyObjectHashTable.get_item
  File "pandas/_libs/hashtable_class_helper.pxi", line 7088, in pandas._libs.hashtable.PyObjectHashTable.get_item
KeyError: 'highlight'

The above exception was the direct cause of the following exception:

Traceback (most recent call last):
  File "/home/airflow/.local/lib/python3.8/site-packages/airflow/models/taskinstance.py", line 433, in _execute_task
    result = execute_callable(context=context, **execute_callable_kwargs)
  File "/home/airflow/.local/lib/python3.8/site-packages/airflow/operators/python.py", line 199, in execute
    return_value = self.execute_callable()
  File "/home/airflow/.local/lib/python3.8/site-packages/airflow/operators/python.py", line 216, in execute_callable
    return self.python_callable(*self.op_args, **self.op_kwargs)
  File "/opt/airflow/dags/dbt_visualization.py", line 53, in _generate_visualizations
    if row['highlight']:
  File "/home/airflow/.local/lib/python3.8/site-packages/pandas/core/series.py", line 1007, in __getitem__
    return self._get_value(key)
  File "/home/airflow/.local/lib/python3.8/site-packages/pandas/core/series.py", line 1116, in _get_value
    loc = self.index.get_loc(label)
  File "/home/airflow/.local/lib/python3.8/site-packages/pandas/core/indexes/base.py", line 3655, in get_loc
    raise KeyError(key) from err
KeyError: 'highlight'
[2024-04-15T17:07:00.556+0000] {taskinstance.py:1138} INFO - Marking task as UP_FOR_RETRY. dag_id=dbt_visualization, task_id=generate_visualizations, execution_date=20240415T170657, start_date=20240415T170700, end_date=20240415T170700
[2024-04-15T17:07:00.569+0000] {logging_mixin.py:188} WARNING - /home/***/.local/lib/python3.8/site-packages/***/utils/email.py:154 RemovedInAirflow3Warning: Fetching SMTP credentials from configuration variables will be deprecated in a future release. Please set credentials using a connection instead.
[2024-04-15T17:07:00.570+0000] {configuration.py:1046} WARNING - section/key [smtp/smtp_user] not found in config
[2024-04-15T17:07:00.570+0000] {email.py:270} INFO - Email alerting: attempt 1
[2024-04-15T17:07:00.572+0000] {email.py:281} INFO - Sent an alert email to ['66130047@dpu.ac.th']
[2024-04-15T17:07:00.598+0000] {standard_task_runner.py:107} ERROR - Failed to execute job 119 for task generate_visualizations ('highlight'; 6315)
[2024-04-15T17:07:00.620+0000] {local_task_job_runner.py:234} INFO - Task exited with return code 1
[2024-04-15T17:07:00.651+0000] {taskinstance.py:3281} INFO - 0 downstream tasks scheduled from follow-on schedule check
