[2024-04-15T15:57:27.029+0000] {taskinstance.py:1957} INFO - Dependencies all met for dep_context=non-requeueable deps ti=<TaskInstance: dbt_visualization.generate_visualizations scheduled__2024-04-14T00:00:00+00:00 [queued]>
[2024-04-15T15:57:27.039+0000] {taskinstance.py:1957} INFO - Dependencies all met for dep_context=requeueable deps ti=<TaskInstance: dbt_visualization.generate_visualizations scheduled__2024-04-14T00:00:00+00:00 [queued]>
[2024-04-15T15:57:27.039+0000] {taskinstance.py:2171} INFO - Starting attempt 2 of 2
[2024-04-15T15:57:27.078+0000] {taskinstance.py:2192} INFO - Executing <Task(PythonOperator): generate_visualizations> on 2024-04-14 00:00:00+00:00
[2024-04-15T15:57:27.088+0000] {standard_task_runner.py:60} INFO - Started process 196 to run task
[2024-04-15T15:57:27.092+0000] {standard_task_runner.py:87} INFO - Running: ['***', 'tasks', 'run', 'dbt_visualization', 'generate_visualizations', 'scheduled__2024-04-14T00:00:00+00:00', '--job-id', '97', '--raw', '--subdir', 'DAGS_FOLDER/dbt_visualization.py', '--cfg-path', '/tmp/tmplipt2h_9']
[2024-04-15T15:57:27.096+0000] {standard_task_runner.py:88} INFO - Job 97: Subtask generate_visualizations
[2024-04-15T15:57:27.182+0000] {task_command.py:423} INFO - Running <TaskInstance: dbt_visualization.generate_visualizations scheduled__2024-04-14T00:00:00+00:00 [running]> on host ec3d883e7b78
[2024-04-15T15:57:27.293+0000] {taskinstance.py:2481} INFO - Exporting env vars: AIRFLOW_CTX_DAG_EMAIL='66130047@dpu.ac.th' AIRFLOW_CTX_DAG_OWNER='***' AIRFLOW_CTX_DAG_ID='dbt_visualization' AIRFLOW_CTX_TASK_ID='generate_visualizations' AIRFLOW_CTX_EXECUTION_DATE='2024-04-14T00:00:00+00:00' AIRFLOW_CTX_TRY_NUMBER='2' AIRFLOW_CTX_DAG_RUN_ID='scheduled__2024-04-14T00:00:00+00:00'
[2024-04-15T15:57:27.306+0000] {base.py:83} INFO - Using connection ID 'my_***_conn' for task execution.
[2024-04-15T15:57:27.319+0000] {taskinstance.py:2699} ERROR - Task failed with exception
Traceback (most recent call last):
  File "/home/airflow/.local/lib/python3.8/site-packages/airflow/models/taskinstance.py", line 433, in _execute_task
    result = execute_callable(context=context, **execute_callable_kwargs)
  File "/home/airflow/.local/lib/python3.8/site-packages/airflow/operators/python.py", line 199, in execute
    return_value = self.execute_callable()
  File "/home/airflow/.local/lib/python3.8/site-packages/airflow/operators/python.py", line 216, in execute_callable
    return self.python_callable(*self.op_args, **self.op_kwargs)
  File "/opt/airflow/dags/dbt_visualization.py", line 28, in _generate_visualizations
    cursor.execute(sql)
psycopg2.errors.UndefinedTable: relation "trending_topics" does not exist
LINE 2:         select * from trending_topics
                              ^

[2024-04-15T15:57:27.332+0000] {taskinstance.py:1138} INFO - Marking task as FAILED. dag_id=dbt_visualization, task_id=generate_visualizations, execution_date=20240414T000000, start_date=20240415T155727, end_date=20240415T155727
[2024-04-15T15:57:27.348+0000] {logging_mixin.py:188} WARNING - /home/***/.local/lib/python3.8/site-packages/***/utils/email.py:154 RemovedInAirflow3Warning: Fetching SMTP credentials from configuration variables will be deprecated in a future release. Please set credentials using a connection instead.
[2024-04-15T15:57:27.348+0000] {configuration.py:1046} WARNING - section/key [smtp/smtp_user] not found in config
[2024-04-15T15:57:27.349+0000] {email.py:270} INFO - Email alerting: attempt 1
[2024-04-15T15:57:27.350+0000] {email.py:281} INFO - Sent an alert email to ['66130047@dpu.ac.th']
[2024-04-15T15:57:27.385+0000] {standard_task_runner.py:107} ERROR - Failed to execute job 97 for task generate_visualizations (relation "trending_topics" does not exist
LINE 2:         select * from trending_topics
                              ^
; 196)
[2024-04-15T15:57:27.431+0000] {local_task_job_runner.py:234} INFO - Task exited with return code 1
[2024-04-15T15:57:27.451+0000] {taskinstance.py:3281} INFO - 0 downstream tasks scheduled from follow-on schedule check
