[2024-04-15T17:41:20.418+0000] {taskinstance.py:1957} INFO - Dependencies all met for dep_context=non-requeueable deps ti=<TaskInstance: dbt_visualization.generate_visualizations manual__2024-04-15T17:35:27.312972+00:00 [queued]>
[2024-04-15T17:41:20.424+0000] {taskinstance.py:1957} INFO - Dependencies all met for dep_context=requeueable deps ti=<TaskInstance: dbt_visualization.generate_visualizations manual__2024-04-15T17:35:27.312972+00:00 [queued]>
[2024-04-15T17:41:20.424+0000] {taskinstance.py:2171} INFO - Starting attempt 3 of 3
[2024-04-15T17:41:20.442+0000] {taskinstance.py:2192} INFO - Executing <Task(PythonOperator): generate_visualizations> on 2024-04-15 17:35:27.312972+00:00
[2024-04-15T17:41:20.451+0000] {standard_task_runner.py:60} INFO - Started process 9117 to run task
[2024-04-15T17:41:20.454+0000] {standard_task_runner.py:87} INFO - Running: ['***', 'tasks', 'run', 'dbt_visualization', 'generate_visualizations', 'manual__2024-04-15T17:35:27.312972+00:00', '--job-id', '123', '--raw', '--subdir', 'DAGS_FOLDER/dbt_visualization.py', '--cfg-path', '/tmp/tmpd4juc97r']
[2024-04-15T17:41:20.457+0000] {standard_task_runner.py:88} INFO - Job 123: Subtask generate_visualizations
[2024-04-15T17:41:20.506+0000] {task_command.py:423} INFO - Running <TaskInstance: dbt_visualization.generate_visualizations manual__2024-04-15T17:35:27.312972+00:00 [running]> on host ec3d883e7b78
[2024-04-15T17:41:20.582+0000] {taskinstance.py:2481} INFO - Exporting env vars: AIRFLOW_CTX_DAG_EMAIL='66130047@dpu.ac.th' AIRFLOW_CTX_DAG_OWNER='***' AIRFLOW_CTX_DAG_ID='dbt_visualization' AIRFLOW_CTX_TASK_ID='generate_visualizations' AIRFLOW_CTX_EXECUTION_DATE='2024-04-15T17:35:27.312972+00:00' AIRFLOW_CTX_TRY_NUMBER='3' AIRFLOW_CTX_DAG_RUN_ID='manual__2024-04-15T17:35:27.312972+00:00'
[2024-04-15T17:41:20.590+0000] {base.py:83} INFO - Using connection ID 'my_***_conn' for task execution.
[2024-04-15T17:41:20.600+0000] {logging_mixin.py:188} WARNING - /opt/***/dags/dbt_visualization.py:29 UserWarning: pandas only supports SQLAlchemy connectable (engine/connection) or database string URI or sqlite3 DBAPI2 connection. Other DBAPI2 objects are not tested. Please consider using SQLAlchemy.
[2024-04-15T17:41:20.680+0000] {logging_mixin.py:188} WARNING - /opt/***/dags/dbt_visualization.py:38 UserWarning: pandas only supports SQLAlchemy connectable (engine/connection) or database string URI or sqlite3 DBAPI2 connection. Other DBAPI2 objects are not tested. Please consider using SQLAlchemy.
[2024-04-15T17:41:20.686+0000] {logging_mixin.py:188} WARNING - /opt/***/dags/dbt_visualization.py:52 UserWarning: pandas only supports SQLAlchemy connectable (engine/connection) or database string URI or sqlite3 DBAPI2 connection. Other DBAPI2 objects are not tested. Please consider using SQLAlchemy.
[2024-04-15T17:41:20.687+0000] {taskinstance.py:2699} ERROR - Task failed with exception
Traceback (most recent call last):
  File "/home/airflow/.local/lib/python3.8/site-packages/pandas/core/indexes/base.py", line 3653, in get_loc
    return self._engine.get_loc(casted_key)
  File "pandas/_libs/index.pyx", line 147, in pandas._libs.index.IndexEngine.get_loc
  File "pandas/_libs/index.pyx", line 176, in pandas._libs.index.IndexEngine.get_loc
  File "pandas/_libs/hashtable_class_helper.pxi", line 7080, in pandas._libs.hashtable.PyObjectHashTable.get_item
  File "pandas/_libs/hashtable_class_helper.pxi", line 7088, in pandas._libs.hashtable.PyObjectHashTable.get_item
KeyError: 'metric1'

The above exception was the direct cause of the following exception:

Traceback (most recent call last):
  File "/home/airflow/.local/lib/python3.8/site-packages/airflow/models/taskinstance.py", line 433, in _execute_task
    result = execute_callable(context=context, **execute_callable_kwargs)
  File "/home/airflow/.local/lib/python3.8/site-packages/airflow/operators/python.py", line 199, in execute
    return_value = self.execute_callable()
  File "/home/airflow/.local/lib/python3.8/site-packages/airflow/operators/python.py", line 216, in execute_callable
    return self.python_callable(*self.op_args, **self.op_kwargs)
  File "/opt/airflow/dags/dbt_visualization.py", line 55, in _generate_visualizations
    ax.plot(df['metric1'], df['metric2'])  # Replace metric1 and metric2 with actual column names
  File "/home/airflow/.local/lib/python3.8/site-packages/pandas/core/frame.py", line 3761, in __getitem__
    indexer = self.columns.get_loc(key)
  File "/home/airflow/.local/lib/python3.8/site-packages/pandas/core/indexes/base.py", line 3655, in get_loc
    raise KeyError(key) from err
KeyError: 'metric1'
[2024-04-15T17:41:20.697+0000] {taskinstance.py:1138} INFO - Marking task as FAILED. dag_id=dbt_visualization, task_id=generate_visualizations, execution_date=20240415T173527, start_date=20240415T174120, end_date=20240415T174120
[2024-04-15T17:41:20.708+0000] {logging_mixin.py:188} WARNING - /home/***/.local/lib/python3.8/site-packages/***/utils/email.py:154 RemovedInAirflow3Warning: Fetching SMTP credentials from configuration variables will be deprecated in a future release. Please set credentials using a connection instead.
[2024-04-15T17:41:20.708+0000] {configuration.py:1046} WARNING - section/key [smtp/smtp_user] not found in config
[2024-04-15T17:41:20.708+0000] {email.py:270} INFO - Email alerting: attempt 1
[2024-04-15T17:41:20.709+0000] {email.py:281} INFO - Sent an alert email to ['66130047@dpu.ac.th']
[2024-04-15T17:41:20.729+0000] {standard_task_runner.py:107} ERROR - Failed to execute job 123 for task generate_visualizations ('metric1'; 9117)
[2024-04-15T17:41:20.746+0000] {local_task_job_runner.py:234} INFO - Task exited with return code 1
[2024-04-15T17:41:20.764+0000] {taskinstance.py:3281} INFO - 0 downstream tasks scheduled from follow-on schedule check
